{"errorMessage": "002002 (42710): 01b58af3-3202-af43-0000-0975017300e6: Uncaught exception of type 'STATEMENT_ERROR' on line 15 at position 4 : SQL compilation error:\nObject 'USERDB_IT_SUPPORT_TEST8ACCT_ROLE' already exists.", "errorType": "ProgrammingError", "requestId": "c15a4acb-06d7-46c0-96d6-7ee1e1345256", "stackTrace": ["  File \"/var/task/lambda_function.py\", line 236, in lambda_handler\n    cursor.execute(str_query)\n", "  File \"/opt/python/snowflake/connector/cursor.py\", line 1080, in execute\n    Error.errorhandler_wrapper(self.connection, self, error_class, errvalue)\n", "  File \"/opt/python/snowflake/connector/errors.py\", line 290, in errorhandler_wrapper\n    handed_over = Error.hand_to_other_handler(\n", "  File \"/opt/python/snowflake/connector/errors.py\", line 345, in hand_to_other_handler\n    cursor.errorhandler(connection, cursor, error_class, error_value)\n", "  File \"/opt/python/snowflake/connector/errors.py\", line 221, in default_errorhandler\n    raise error_class(\n"]}